Workbook

Sheet Sheet1
A1: Index | B1: Hex | C1: Name | D1: Custom | E1: Base | F1: Map | G1: Attr | H1: Error
A2: 0 | B2: =RIGHT("0"&DEC2HEX(A2),2) -> 00 | C2: Empty | D2: 1 | E2: 1 | F2: =TEXT(DEC2HEX(IF(D2,128 + E2, E2/4)),"00") -> 81 | G2: =IF(D2,"00",VLOOKUP(E2,Sheet2!$A:$B,2)) -> 00 | H2: =IF(D2,"",IF(_xlfn.BITAND(E2,3),"Error","")) | I2: ="DATA BYTE $"&F2&", $"& G2&" ' "&A2&" - "&C2&IF(D2," [*]","") -> DATA BYTE $81, $00 ' 0 - Empty [*]
A3: 1 | B3: =RIGHT("0"&DEC2HEX(A3),2) -> 01 | C3: Zonk | D3: 0 | E3: 196 | F3: =TEXT(DEC2HEX(IF(D3,128 + E3, E3/4)),"00") -> 31 | G3: =IF(D3,"00",VLOOKUP(E3,Sheet2!$A:$B,2)) -> 04 | H3: =IF(D3,"",IF(_xlfn.BITAND(E3,3),"Error","")) | I3: ="DATA BYTE $"&F3&", $"& G3&" ' "&A3&" - "&C3&IF(D3," [*]","") -> DATA BYTE $31, $04 ' 1 - Zonk
A4: 2 | B4: =RIGHT("0"&DEC2HEX(A4),2) -> 02 | C4: Base | D4: 0 | E4: 8 | F4: =TEXT(DEC2HEX(IF(D4,128 + E4, E4/4)),"00") -> 02 | G4: =IF(D4,"00",VLOOKUP(E4,Sheet2!$A:$B,2)) -> 02 | H4: =IF(D4,"",IF(_xlfn.BITAND(E4,3),"Error","")) | I4: ="DATA BYTE $"&F4&", $"& G4&" ' "&A4&" - "&C4&IF(D4," [*]","") -> DATA BYTE $02, $02 ' 2 - Base
A5: 3 | B5: =RIGHT("0"&DEC2HEX(A5),2) -> 03 | C5: Murphy | D5: 0 | E5: 184 | F5: =TEXT(DEC2HEX(IF(D5,128 + E5, E5/4)),"00") -> 2E | G5: =IF(D5,"00",VLOOKUP(E5,Sheet2!$A:$B,2)) -> 00 | H5: =IF(D5,"",IF(_xlfn.BITAND(E5,3),"Error","")) | I5: ="DATA BYTE $"&F5&", $"& G5&" ' "&A5&" - "&C5&IF(D5," [*]","") -> DATA BYTE $2E, $00 ' 3 - Murphy
A6: 4 | B6: =RIGHT("0"&DEC2HEX(A6),2) -> 04 | C6: Infotron | D6: 1 | E6: 13 | F6: =TEXT(DEC2HEX(IF(D6,128 + E6, E6/4)),"00") -> 8D | G6: =IF(D6,"00",VLOOKUP(E6,Sheet2!$A:$B,2)) -> 00 | H6: =IF(D6,"",IF(_xlfn.BITAND(E6,3),"Error","")) | I6: ="DATA BYTE $"&F6&", $"& G6&" ' "&A6&" - "&C6&IF(D6," [*]","") -> DATA BYTE $8D, $00 ' 4 - Infotron [*]
A7: 5 | B7: =RIGHT("0"&DEC2HEX(A7),2) -> 05 | C7: RAM chip - Chip | D7: 0 | E7: 124 | F7: =TEXT(DEC2HEX(IF(D7,128 + E7, E7/4)),"00") -> 1F | G7: =IF(D7,"00",VLOOKUP(E7,Sheet2!$A:$B,2)) -> 04 | H7: =IF(D7,"",IF(_xlfn.BITAND(E7,3),"Error","")) | I7: ="DATA BYTE $"&F7&", $"& G7&" ' "&A7&" - "&C7&IF(D7," [*]","") -> DATA BYTE $1F, $04 ' 5 - RAM chip - Chip
A8: 6 | B8: =RIGHT("0"&DEC2HEX(A8),2) -> 06 | C8: Wall | D8: 0 | E8: 24 | F8: =TEXT(DEC2HEX(IF(D8,128 + E8, E8/4)),"00") -> 06 | G8: =IF(D8,"00",VLOOKUP(E8,Sheet2!$A:$B,2)) -> 04 | H8: =IF(D8,"",IF(_xlfn.BITAND(E8,3),"Error","")) | I8: ="DATA BYTE $"&F8&", $"& G8&" ' "&A8&" - "&C8&IF(D8," [*]","") -> DATA BYTE $06, $04 ' 6 - Wall
A9: 7 | B9: =RIGHT("0"&DEC2HEX(A9),2) -> 07 | C9: Exit | D9: 0 | E9: 28 | F9: =TEXT(DEC2HEX(IF(D9,128 + E9, E9/4)),"00") -> 07 | G9: =IF(D9,"00",VLOOKUP(E9,Sheet2!$A:$B,2)) -> 04 | H9: =IF(D9,"",IF(_xlfn.BITAND(E9,3),"Error","")) | I9: ="DATA BYTE $"&F9&", $"& G9&" ' "&A9&" - "&C9&IF(D9," [*]","") -> DATA BYTE $07, $04 ' 7 - Exit
A10: 8 | B10: =RIGHT("0"&DEC2HEX(A10),2) -> 08 | C10: Floppy - Orange | D10: 0 | E10: 192 | F10: =TEXT(DEC2HEX(IF(D10,128 + E10, E10/4)),"00") -> 30 | G10: =IF(D10,"00",VLOOKUP(E10,Sheet2!$A:$B,2)) -> 06 | H10: =IF(D10,"",IF(_xlfn.BITAND(E10,3),"Error","")) | I10: ="DATA BYTE $"&F10&", $"& G10&" ' "&A10&" - "&C10&IF(D10," [*]","") -> DATA BYTE $30, $06 ' 8 - Floppy - Orange
A11: 9 | B11: =RIGHT("0"&DEC2HEX(A11),2) -> 09 | C11: Port - Right | D11: 0 | E11: 20 | F11: =TEXT(DEC2HEX(IF(D11,128 + E11, E11/4)),"00") -> 05 | G11: =IF(D11,"00",VLOOKUP(E11,Sheet2!$A:$B,2)) -> 04 | H11: =IF(D11,"",IF(_xlfn.BITAND(E11,3),"Error","")) | I11: ="DATA BYTE $"&F11&", $"& G11&" ' "&A11&" - "&C11&IF(D11," [*]","") -> DATA BYTE $05, $04 ' 9 - Port - Right
A12: 10 | B12: =RIGHT("0"&DEC2HEX(A12),2) -> 0A | C12: Port - Down | D12: 0 | E12: 12 | F12: =TEXT(DEC2HEX(IF(D12,128 + E12, E12/4)),"00") -> 03 | G12: =IF(D12,"00",VLOOKUP(E12,Sheet2!$A:$B,2)) -> 04 | H12: =IF(D12,"",IF(_xlfn.BITAND(E12,3),"Error","")) | I12: ="DATA BYTE $"&F12&", $"& G12&" ' "&A12&" - "&C12&IF(D12," [*]","") -> DATA BYTE $03, $04 ' 10 - Port - Down
A13: 11 | B13: =RIGHT("0"&DEC2HEX(A13),2) -> 0B | C13: Port - Left | D13: 1 | E13: 2 | F13: =TEXT(DEC2HEX(IF(D13,128 + E13, E13/4)),"00") -> 82 | G13: =IF(D13,"00",VLOOKUP(E13,Sheet2!$A:$B,2)) -> 00 | H13: =IF(D13,"",IF(_xlfn.BITAND(E13,3),"Error","")) | I13: ="DATA BYTE $"&F13&", $"& G13&" ' "&A13&" - "&C13&IF(D13," [*]","") -> DATA BYTE $82, $00 ' 11 - Port - Left [*]
... A41: 39 | B41: =RIGHT("0"&DEC2HEX(A41),2) -> 27 | C41: RAM chip - Bottom | D41: 0 | E41: 132 | F41: =TEXT(DEC2HEX(IF(D41,128 + E41, E41/4)),"00") -> 21 | G41: =IF(D41,"00",VLOOKUP(E41,Sheet2!$A:$B,2)) -> 04 | H41: =IF(D41,"",IF(_xlfn.BITAND(E41,3),"Error","")) | I41: ="DATA BYTE $"&F41&", $"& G41&" ' "&A41&" - "&C41&IF(D41," [*]","") -> DATA BYTE $21, $04 ' 39 - RAM chip - Bottom
A42: 40 | B42: =RIGHT("0"&DEC2HEX(A42),2) -> 28 | C42: Border - Corner | D42: 0 | E42: 4 | F42: =TEXT(DEC2HEX(IF(D42,128 + E42, E42/4)),"00") -> 01 | G42: =IF(D42,"00",VLOOKUP(E42,Sheet2!$A:$B,2)) -> 04 | I42: ="DATA BYTE $"&F42&", $"& G42&" ' "&A42&" - "&C42&IF(D42," [*]","") -> DATA BYTE $01, $04 ' 40 - Border - Corner
A43: 41 | B43: =RIGHT("0"&DEC2HEX(A43),2) -> 29 | C43: Border - Horizontal | D43: 1 | E43: 11 | F43: =TEXT(DEC2HEX(IF(D43,128 + E43, E43/4)),"00") -> 8B | G43: =IF(D43,"00",VLOOKUP(E43,Sheet2!$A:$B,2)) -> 00 | I43: ="DATA BYTE $"&F43&", $"& G43&" ' "&A43&" - "&C43&IF(D43," [*]","") -> DATA BYTE $8B, $00 ' 41 - Border - Horizontal [*]
A44: 42 | B44: =RIGHT("0"&DEC2HEX(A44),2) -> 2A | C44: Border - Vertical | D44: 1 | E44: 12 | F44: =TEXT(DEC2HEX(IF(D44,128 + E44, E44/4)),"00") -> 8C | G44: =IF(D44,"00",VLOOKUP(E44,Sheet2!$A:$B,2)) -> 00 | I44: ="DATA BYTE $"&F44&", $"& G44&" ' "&A44&" - "&C44&IF(D44," [*]","") -> DATA BYTE $8C, $00 ' 42 - Border - Vertical [*]
A45: 43 | B45: =RIGHT("0"&DEC2HEX(A45),2) -> 2B | C45: Snik snak - U (Dup) | D45: 0 | E45: 212 | F45: =TEXT(DEC2HEX(IF(D45,128 + E45, E45/4)),"00") -> 35 | G45: =IF(D45,"00",VLOOKUP(E45,Sheet2!$A:$B,2)) -> 00 | H45: =IF(D45,"",IF(_xlfn.BITAND(E45,3),"Error","")) | I45: ="DATA BYTE $"&F45&", $"& G45&" ' "&A45&" - "&C45&IF(D45," [*]","") -> DATA BYTE $35, $00 ' 43 - Snik snak - U (Dup)
A46: 44 | B46: =RIGHT("0"&DEC2HEX(A46),2) -> 2C | C46: Snik Snak - UL | D46: 0 | E46: 216 | F46: =TEXT(DEC2HEX(IF(D46,128 + E46, E46/4)),"00") -> 36 | G46: =IF(D46,"00",VLOOKUP(E46,Sheet2!$A:$B,2)) -> 00 | I46: ="DATA BYTE $"&F46&", $"& G46&" ' "&A46&" - "&C46&IF(D46," [*]","") -> DATA BYTE $36, $00 ' 44 - Snik Snak - UL
A47: 45 | B47: =RIGHT("0"&DEC2HEX(A47),2) -> 2D | C47: Snik Snak - L | D47: 0 | E47: 208 | F47: =TEXT(DEC2HEX(IF(D47,128 + E47, E47/4)),"00") -> 34 | G47: =IF(D47,"00",VLOOKUP(E47,Sheet2!$A:$B,2)) -> 00 | I47: ="DATA BYTE $"&F47&", $"& G47&" ' "&A47&" - "&C47&IF(D47," [*]","") -> DATA BYTE $34, $00 ' 45 - Snik Snak - L
A48: 46 | B48: =RIGHT("0"&DEC2HEX(A48),2) -> 2E | C48: Snik Snak - DL | D48: 1 | E48: 16 | F48: =TEXT(DEC2HEX(IF(D48,128 + E48, E48/4)),"00") -> 90 | G48: =IF(D48,"00",VLOOKUP(E48,Sheet2!$A:$B,2)) -> 00 | I48: ="DATA BYTE $"&F48&", $"& G48&" ' "&A48&" - "&C48&IF(D48," [*]","") -> DATA BYTE $90, $00 ' 46 - Snik Snak - DL [*]
A49: 47 | B49: =RIGHT("0"&DEC2HEX(A49),2) -> 2F | C49: Snik Snak - D | D49: 1 | E49: 17 | F49: =TEXT(DEC2HEX(IF(D49,128 + E49, E49/4)),"00") -> 91 | G49: =IF(D49,"00",VLOOKUP(E49,Sheet2!$A:$B,2)) -> 00 | I49: ="DATA BYTE $"&F49&", $"& G49&" ' "&A49&" - "&C49&IF(D49," [*]","") -> DATA BYTE $91, $00 ' 47 - Snik Snak - D [*]
A50: 48 | B50: =RIGHT("0"&DEC2HEX(A50),2) -> 30 | C50: Snik Snak - DR | D50: 1 | E50: 18 | F50: =TEXT(DEC2HEX(IF(D50,128 + E50, E50/4)),"00") -> 92 | G50: =IF(D50,"00",VLOOKUP(E50,Sheet2!$A:$B,2)) -> 00 | I50: ="DATA BYTE $"&F50&", $"& G50&" ' "&A50&" - "&C50&IF(D50," [*]","") -> DATA BYTE $92, $00 ' 48 - Snik Snak - DR [*]
A51: 49 | B51: =RIGHT("0"&DEC2HEX(A51),2) -> 31 | C51: Snik Snak - R | D51: 1 | E51: 19 | F51: =TEXT(DEC2HEX(IF(D51,128 + E51, E51/4)),"00") -> 93 | G51: =IF(D51,"00",VLOOKUP(E51,Sheet2!$A:$B,2)) -> 00 | I51: ="DATA BYTE $"&F51&", $"& G51&" ' "&A51&" - "&C51&IF(D51," [*]","") -> DATA BYTE $93, $00 ' 49 - Snik Snak - R [*]
A52: 50 | B52: =RIGHT("0"&DEC2HEX(A52),2) -> 32 | C52: Snik Snak - UR | D52: 1 | E52: 20 | F52: =TEXT(DEC2HEX(IF(D52,128 + E52, E52/4)),"00") -> 94 | G52: =IF(D52,"00",VLOOKUP(E52,Sheet2!$A:$B,2)) -> 00 | I52: ="DATA BYTE $"&F52&", $"& G52&" ' "&A52&" - "&C52&IF(D52," [*]","") -> DATA BYTE $94, $00 ' 50 - Snik Snak - UR [*]
A53: 51 | B53: =RIGHT("0"&DEC2HEX(A53),2) -> 33 | C53: Zonk - H | D53: 0 | E53: 196 | F53: =TEXT(DEC2HEX(IF(D53,128 + E53, E53/4)),"00") -> 31 | G53: =IF(D53,"00",VLOOKUP(E53,Sheet2!$A:$B,2)) -> 04 | I53: ="DATA BYTE $"&F53&", $"& G53&" ' "&A53&" - "&C53&IF(D53," [*]","") -> DATA BYTE $31, $04 ' 51 - Zonk - H
A54: 52 | B54: =RIGHT("0"&DEC2HEX(A54),2) -> 34 | C54: Zonk - HL | D54: 1 | E54: 21 | F54: =TEXT(DEC2HEX(IF(D54,128 + E54, E54/4)),"00") -> 95 | G54: =IF(D54,"00",VLOOKUP(E54,Sheet2!$A:$B,2)) -> 00 | I54: ="DATA BYTE $"&F54&", $"& G54&" ' "&A54&" - "&C54&IF(D54," [*]","") -> DATA BYTE $95, $00 ' 52 - Zonk - HL [*]
A55: 53 | B55: =RIGHT("0"&DEC2HEX(A55),2) -> 35 | C55: Zonk - V | D55: 0 | E55: 204 | F55: =TEXT(DEC2HEX(IF(D55,128 + E55, E55/4)),"00") -> 33 | G55: =IF(D55,"00",VLOOKUP(E55,Sheet2!$A:$B,2)) -> 04 | I55: ="DATA BYTE $"&F55&", $"& G55&" ' "&A55&" - "&C55&IF(D55," [*]","") -> DATA BYTE $33, $04 ' 53 - Zonk - V
A56: 54 | B56: =RIGHT("0"&DEC2HEX(A56),2) -> 36 | C56: Zonk - VL | D56: 0 | E56: 200 | F56: =TEXT(DEC2HEX(IF(D56,128 + E56, E56/4)),"00") -> 32 | G56: =IF(D56,"00",VLOOKUP(E56,Sheet2!$A:$B,2)) -> 04 | I56: ="DATA BYTE $"&F56&", $"& G56&" ' "&A56&" - "&C56&IF(D56," [*]","") -> DATA BYTE $32, $04 ' 54 - Zonk - VL
A57: 55 | B57: =RIGHT("0"&DEC2HEX(A57),2) -> 37 | C57: Murphy | D57: 1 | E57: 22 | F57: =TEXT(DEC2HEX(IF(D57,128 + E57, E57/4)),"00") -> 96 | G57: =IF(D57,"00",VLOOKUP(E57,Sheet2!$A:$B,2)) -> 00 | H57: =IF(D57,"",IF(_xlfn.BITAND(E57,3),"Error","")) | I57: ="DATA BYTE $"&F57&", $"& G57&" ' "&A57&" - "&C57&IF(D57," [*]","") -> DATA BYTE $96, $00 ' 55 - Murphy [*]
A58: 56 | B58: =RIGHT("0"&DEC2HEX(A58),2) -> 38 | C58: Explode 0 | D58: 0 | E58: 32 | F58: =TEXT(DEC2HEX(IF(D58,128 + E58, E58/4)),"00") -> 08 | G58: 04 | H58: =IF(D58,"",IF(_xlfn.BITAND(E58,3),"Error","")) | I58: ="DATA BYTE $"&F58&", $"& G58&" ' "&A58&" - "&C58&IF(D58," [*]","") -> DATA BYTE $08, $04 ' 56 - Explode 0
A59: 57 | B59: =RIGHT("0"&DEC2HEX(A59),2) -> 39 | C59: Explode 1 | D59: 0 | E59: 36 | F59: =TEXT(DEC2HEX(IF(D59,128 + E59, E59/4)),"00") -> 09 | G59: 04 | H59: =IF(D59,"",IF(_xlfn.BITAND(E59,3),"Error","")) | I59: ="DATA BYTE $"&F59&", $"& G59&" ' "&A59&" - "&C59&IF(D59," [*]","") -> DATA BYTE $09, $04 ' 57 - Explode 1
A60: 58 | B60: =RIGHT("0"&DEC2HEX(A60),2) -> 3A | C60: Explode 2 | D60: 0 | E60: 40 | F60: =RIGHT("0"&DEC2HEX(IF(D60,128 + E60, E60/4)),2) -> 0A | G60: 04 | H60: =IF(D60,"",IF(_xlfn.BITAND(E60,3),"Error","")) | I60: ="DATA BYTE $"&F60&", $"& G60&" ' "&A60&" - "&C60&IF(D60," [*]","") -> DATA BYTE $0A, $04 ' 58 - Explode 2
A61: 59 | B61: =RIGHT("0"&DEC2HEX(A61),2) -> 3B | C61: Explode 3 | D61: 0 | E61: 44 | F61: =RIGHT("0"&DEC2HEX(IF(D61,128 + E61, E61/4)),2) -> 0B | G61: 04 | H61: =IF(D61,"",IF(_xlfn.BITAND(E61,3),"Error","")) | I61: ="DATA BYTE $"&F61&", $"& G61&" ' "&A61&" - "&C61&IF(D61," [*]","") -> DATA BYTE $0B, $04 ' 59 - Explode 3
A62: 60 | B62: =RIGHT("0"&DEC2HEX(A62),2) -> 3C | C62: Explode 4 | D62: 0 | E62: 48 | F62: =RIGHT("0"&DEC2HEX(IF(D62,128 + E62, E62/4)),2) -> 0C | G62: 04 | H62: =IF(D62,"",IF(_xlfn.BITAND(E62,3),"Error","")) | I62: ="DATA BYTE $"&F62&", $"& G62&" ' "&A62&" - "&C62&IF(D62," [*]","") -> DATA BYTE $0C, $04 ' 60 - Explode 4
A63: 61 | B63: =RIGHT("0"&DEC2HEX(A63),2) -> 3D | C63: Explode 5 | D63: 0 | E63: 52 | F63: =RIGHT("0"&DEC2HEX(IF(D63,128 + E63, E63/4)),2) -> 0D | G63: 04 | H63: =IF(D63,"",IF(_xlfn.BITAND(E63,3),"Error","")) | I63: ="DATA BYTE $"&F63&", $"& G63&" ' "&A63&" - "&C63&IF(D63," [*]","") -> DATA BYTE $0D, $04 ' 61 - Explode 5
A64: 62 | B64: =RIGHT("0"&DEC2HEX(A64),2) -> 3E | C64: Explode 6 | D64: 0 | E64: 56 | F64: =RIGHT("0"&DEC2HEX(IF(D64,128 + E64, E64/4)),2) -> 0E | G64: 04 | H64: =IF(D64,"",IF(_xlfn.BITAND(E64,3),"Error","")) | I64: ="DATA BYTE $"&F64&", $"& G64&" ' "&A64&" - "&C64&IF(D64," [*]","") -> DATA BYTE $0E, $04 ' 62 - Explode 6
A65: 63 | B65: =RIGHT("0"&DEC2HEX(A65),2) -> 3F
A66: 64 | B66: =RIGHT("0"&DEC2HEX(A66),2) -> 40
A67: 65 | B67: =RIGHT("0"&DEC2HEX(A67),2) -> 41
...

Sheet Sheet2
A1: 0 | B1: =TEXT(C1,"00") -> 00 | C1: 0
A2: 1 | B2: =TEXT(C2,"00") -> 00 | C2: 0
A3: 2 | B3: =TEXT(C3,"00") -> 04 | C3: 4
A4: 3 | B4: =TEXT(C4,"00") -> 04 | C4: 4
A5: 4 | B5: =TEXT(C5,"00") -> 04 | C5: 4
A6: 5 | B6: =TEXT(C6,"00") -> 04 | C6: 4
A7: 6 | B7: =TEXT(C7,"00") -> 04 | C7: 4
A8: 7 | B8: =TEXT(C8,"00") -> 04 | C8: 4
A9: 8 | B9: =TEXT(C9,"00") -> 02 | C9: 2
A10: 9 | B10: =TEXT(C10,"00") -> 02 | C10: 2
A11: 10 | B11: =TEXT(C11,"00") -> 02 | C11: 2
A12: 11 | B12: =TEXT(C12,"00") -> 02 | C12: 2
... A32: 31 | B32: =TEXT(C32,"00") -> 04 | C32: 4
A33: 32 | B33: =TEXT(C33,"00") -> 00
A34: 33 | B34: =TEXT(C34,"00") -> 00
A35: 34 | B35: =TEXT(C35,"00") -> 00
A36: 35 | B36: =TEXT(C36,"00") -> 00
A37: 36 | B37: =TEXT(C37,"00") -> 00
A38: 37 | B38: =TEXT(C38,"00") -> 00
A39: 38 | B39: =TEXT(C39,"00") -> 00
A40: 39 | B40: =TEXT(C40,"00") -> 00
A41: 40 | B41: =TEXT(C41,"00") -> 00
A42: 41 | B42: =TEXT(C42,"00") -> 00
A43: 42 | B43: =TEXT(C43,"00") -> 00
A44: 43 | B44: =TEXT(C44,"00") -> 00
... A96: 95 | B96: =TEXT(C96,"00") -> 00
A97: 96 | B97: =TEXT(C97,"00") -> 0C | C97: 0C
A98: 97 | B98: =TEXT(C98,"00") -> 0C | C98: 0C
A99: 98 | B99: =TEXT(C99,"00") -> 0C | C99: 0C
A100: 99 | B100: =TEXT(C100,"00") -> 0C | C100: 0C
A101: 100 | B101: =TEXT(C101,"00") -> 02 | C101: 2
A102: 101 | B102: =TEXT(C102,"00") -> 02 | C102: 2
A103: 102 | B103: =TEXT(C103,"00") -> 02 | C103: 2
A104: 103 | B104: =TEXT(C104,"00") -> 02 | C104: 2
A105: 104 | B105: =TEXT(C105,"00") -> 00 | C105: 0
A106: 105 | B106: =TEXT(C106,"00") -> 00 | C106: 0
A107: 106 | B107: =TEXT(C107,"00") -> 00 | C107: 0
A108: 107 | B108: =TEXT(C108,"00") -> 00 | C108: 0
A109: 108 | B109: =TEXT(C109,"00") -> 0A | C109: 0A
A110: 109 | B110: =TEXT(C110,"00") -> 0A | C110: 0A
...

Sheet Sheet3
